Workbook

Sheet Study Register
A2: FRP bridge-deck and slab evidence register
A3: 31 publication records. Reported counts include controls and related reports; they are not additive independent-test counts.
A6: Reference ID | B6: Citation | C6: Evidence class | D6: Response topic | E6: Reported units n | F6: Count definition | G6: Named records extracted n | H6: Test scope | I6: Geometry / scale | J6: Support / restraint | K6: Concrete | L6: Reinforcement | M6: Loading protocol | N6: Reported findings | O6: FRP units n | P6: Steel controls n | Q6: Related program group | R6: Overlap and independence | S6: Unrecovered data / limitations | T6: Online publication date | U6: Issue year | V6: Original row IDs | W6: Source verification | X6: Source locator | Y6: Source URL | Z6: DOI
A7: R002 | B7: Abdul-Salam, B. (2014) | C7: Slab experimental report | D7: One-way shear | E7: 22 | F7: Publication-reported specimens/units; do not sum across related reports | G7: =COUNTIFS(Specimens!$B$7:$B$76,A7) -> 22 | H7: Simply supported shear-critical one-way slabs | I7: length 4000 mm; width 1000 mm; thickness 200 mm; slab span 3500 mm | J7: Simply supported | K7: Not recovered | L7: GFRP; CFRP; Steel | M7: Two equal full-width line loads; four-point bending | N7: Extracted failure loads 188–426 kN. Reported outcomes: Diagonal tension, Shear compression with FRP shearing-off, Diagonal tension with FRP shearing-off, Shear bond, Shear compression, Shear, Flexural compression | O7: 21 | P7: 1 | Q7: Abdul-Salam thesis / 2013 / 2016 | R7: Thesis chapters4,5 and6 overlap:22 unique slabs; 9CFRP in chapter4 and reused subset in chapter5, not additive. Conference2013 and article2016 may report same experimental family. Table3-3 and5-1 have inconsistent Ef and some ratios; no pooled model validation until resolved. | S7: See source and specimen-specific notes | U7: 2014 | V7: 58 | W7: Author-deposited full doctoral thesis Tables3-3,4-1,5-4 | X7: Table3-3 p70, Table4-1 p83, Table5-4 p133 | Y7: https://www.researchgate.net/publication/260165629_BEHAVIOUR_OF_SHEAR_CRITICAL_FRP_REINFORCED_CONCRETE_ONE-WAY_SLABS
A8: R003 | B8: Abdul-Salam, B., Farghaly, A.S., & Benmokrane, B. (2016) | C8: Slab experimental report | D8: One-way shear | F8: Count not recovered | G8: =COUNTIFS(Specimens!$B$7:$B$76,A8) -> 0 | H8: One-way slab experiments and mechanisms; potential thesis/conference overlap. | I8: Not recovered | J8: Not recovered | K8: Not recovered | L8: Not recovered | M8: Not recovered | N8: See cited source; no quantitative result extracted | Q8: Abdul-Salam thesis / 2013 / 2016 | R8: Same experimental family as Abdul-Salam2014; do not count as new tests absent specimen identity comparison. | S8: See source and specimen-specific notes | U8: 2016 | V8: 56 | W8: Publisher bibliographic match; full text not retrieved | X8: Manuscript bibliography | Y8: https://www.sciencedirect.com/science/article/pii/S0950061816316191 | Z8: 10.1016/j.conbuildmat.2016.10.015
A9: R004 | B9: Abdul-Salam, B., Farghaly, A.S., Benmokrane, B. (2013) | C9: Slab experimental report | D9: One-way shear | F9: Count not recovered | G9: =COUNTIFS(Specimens!$B$7:$B$76,A9) -> 0 | H9: CFRP one-way slab conference report; likely subset of 2014 thesis/2016 article. Specimen crosswalk required. | I9: Not recovered | J9: Not recovered | K9: Not recovered | L9: Not recovered | M9: Not recovered | N9: See cited source; no quantitative result extracted | Q9: Abdul-Salam thesis / 2013 / 2016 | R9: CFRP slab report likely subset of Abdul-Salam2014; do not count as independent program. | S9: See source and specimen-specific notes | U9: 2013 | W9: Cited conference paper; exact independent count not verified | X9: Manuscript bibliography
A10: R010 | B10: Aflakisamani, M., Mousa, S., Mohamed, H. M., Ahmed, E. A., & Benmokrane, B. (2023) | C10: Slab experimental report | D10: Serviceability / punching | E10: 4 | F10: Publication-reported specimens/units; do not sum across related reports | G10: =COUNTIFS(Specimens!$B$7:$B$76,A10) -> 0 | H10: LWSCC edge-restrained3 and unrestrained1 full-scale panels | I10: 3000×2500×200mm; concentrated CL-625 wheel simulation | J10: Not recovered | K10: Not recovered | L10: Not recovered | M10: Not recovered | N10: See cited source; no quantitative result extracted | O10: 4 | R10: Full-scale GFRP lightweight SCC bridge-deck laboratory experiments; 2022 conference report in legacy workbook may duplicate. | S10: See source and specimen-specific notes | U10: 2023 | V10: 36 | W10: Primary author/publisher abstract verified; specimen table unavailable | X10: Manuscript bibliography | Y10: https://ascelibrary.org/doi/10.1061/JBENF2.BEENG-5722 | Z10: 10.1061/JBENF2.BEENG-5722
A11: R012 | B11: Al-Sunna, R., Pilakoutas, K., Hajirasouliha, I., & Guadagnini, M. (2012) | C11: Slab experimental report | D11: Deflection | E11: 14 | F11: Slab subset 14 of 28 total beam/slab members | G11: =COUNTIFS(Specimens!$B$7:$B$76,A11) -> 14 | H11: Simply supported one-way slab strips plus separate beam comparator group | I11: length 2350 mm; width 500 mm; thickness 120 mm; slab span 2100 mm | J11: Simply supported | K11: Not recovered | L11: GFRP; CFRP; Steel | M11: Four-point; one service-load cycle then loading to failure | N11: Reported outcomes: Rebar rupture, Almost balanced, Concrete crushing, Reinforcement yielding | O11: 12 | P11: 2 | Q11: Alsunna thesis / Al-Sunna 2012 | R11: Each slab series has a/b replicate; Table5 model ratios are series-level, not 12 independent specimen ratios. Al-Sunna2006 thesis likely same experimental family; do not add counts. | S11: See source and specimen-specific notes | U11: 2012 | W11: Institutional fulltext PDF; Tables1,3–5 and Fig2 verified | X11: Tables1,3,4; manuscript pp.14–15; Fig2 p.17 | Y11: https://eprints.whiterose.ac.uk/id/eprint/85515/1/Deflection%20behaviour%20of%20FRP%20reinforced%20concrete%20beams%20and%20slabs-%20An%20experimental%20investigation.pdf | Z11: 10.1016/j.compositesb.2012.03.007
A12: R015 | B12: Ali, Y. M. S., Wang, X., Guo, H., Liu, S., Li, D., Wu, Z., & Moussa, A. M. A. (2024) | C12: Slab experimental report | D12: Static / fatigue | F12: Count not recovered | G12: =COUNTIFS(Specimens!$B$7:$B$76,A12) -> 0 | H12: BFRP, steel and hybrid bridge-deck slab experiments; possible overlap with Ali 2023 static report in legacy workbook. | I12: Not recovered | J12: Not recovered | K12: Not recovered | L12: Hybrid BFRP/steel | M12: Static and fatigue; effective reinforcement ratio, FRP/steel area ratio, upper fatigue load varied | N12: The abstract reports a regression-based two-million-cycle estimate at an upper fatigue load of 0.34 of static ultimate capacity. This is a model estimate, NOT an observed specimen runout. | R12: Do not infer specimen count or copy the twelve-beam count shown in an unrelated citing-paper preview. | S12: Qualitative fatigue evidence; no individual numerical validation rows | U12: 2024 | V12: 1 | W12: Author paper abstract; full text not obtained | X12: Abstract | Y12: https://www.sciencedirect.com/science/article/abs/pii/S2352012424008592 | Z12: 10.1016/j.istruc.2024.106707
A13: R018 | B13: Alsunna, R. (2006) | C13: Slab experimental report | D13: Deflection | F13: Count not recovered | G13: =COUNTIFS(Specimens!$B$7:$B$76,A13) -> 0 | H13: Thesis involving FRP flexural members; possible overlap with Al-Sunna 2012 mixed beam/slab article. | I13: Not recovered | J13: Not recovered | K13: Not recovered | L13: Not recovered | M13: Not recovered | N13: See cited source; no quantitative result extracted | Q13: Alsunna thesis / Al-Sunna 2012 | R13: Thesis involving FRP flexural members; possible overlap with Al-Sunna 2012 mixed beam/slab article. | S13: Additional specimen geometry, materials and response tables need primary-source extraction | U13: 2006 | W13: Bibliography/title audit; primary details not recovered | X13: Manuscript bibliography
A14: R022 | B14: Benmokrane, B., El-Salakawy, E., El-Ragaby, A., & Lackey, T. (2006) | C14: Field report | D14: Field / serviceability | E14: 1 | F14: field bridge | G14: =COUNTIFS(Specimens!$B$7:$B$76,A14) -> 1 | H14: Morristown Bridge field design and proof testing; failure strength not directly observed. | I14: thickness 230 mm | J14: Not recovered | K14: Not recovered | L14: GFRP | M14: Two calibrated three-axle trucks; 4 single-truck paths plus one paired path; 7 stations, 35 readings/gauge; ambient traffic dynamic response | N14: Named units and measured response records extracted; see Test Results | R14: Morristown Bridge field design and proof testing; failure strength not directly observed. | S14: Field serviceability, construction, loading distribution; no ultimate/fatigue-life validation | U14: 2006 | V14: 16 | W14: User-supplied primary full PDF and author full text | X14: Tables1-2, pp.218-219; field observations pp.220-225 | Y14: https://ascelibrary.org/doi/10.1061/%28ASCE%291084-0702%282006%2911%3A2%28217%29 | Z14: 10.1061/(ASCE)1084-0702(2006)11:2(217)
A15: R023 | B15: Berg, A. C., Bank, L. C., Oliva, M. G., & Russell, J. S. (2006) | C15: Field report | D15: Field / construction / cost | E15: 1 | F15: FRP-reinforced two-span US151 overpass project | G15: =COUNTIFS(Specimens!$B$7:$B$76,A15) -> 0 | H15: Wisconsin bridge construction and cost report; distinguish bar-reinforced deck from formwork system and cost assumptions. | I15: Not recovered | J15: Not recovered | K15: Not recovered | L15: FRP SIP forms, deformed FRP bars, prefabricated pultruded FRP grid | M15: Not recovered | N15: See cited source; no quantitative result extracted | R15: Hybrid structural form/grid/bar system differs from internally bar-reinforced solid slabs. No field test values verified from this paper. | S15: Construction/cost evidence; do not enter into bar-only slab ultimate-load or fatigue validation | U15: 2006 | V15: 15 | W15: Original abstract on paper record | X15: Manuscript bibliography | Y15: https://www.sciencedirect.com/science/article/pii/S0950061805001145 | Z15: 10.1016/j.conbuildmat.2005.02.007
A16: R025 | B16: Bouguerra, K., Ahmed, E. A., El-Gamal, S., & Benmokrane, B. (2011) | C16: Slab experimental report | D16: Punching / CMA | E16: 8 | F16: Publication-reported specimens/units; do not sum across related reports | G16: =COUNTIFS(Specimens!$B$7:$B$76,A16) -> 8 | H16: Edge-restrained full-scale bridge deck panels | I16: length 3000 mm; width 2500 mm; thickness 150–200 mm; slab span 2000 mm | J16: Edge restrained | K16: Not recovered | L16: GFRP; Steel; CFRP | M16: Single central patch; monotonic | N16: Extracted failure loads 362–732 kN. Reported outcomes: Punching shear | O16: 7 | P16: 1 | R16: G-175-N used repeatedly as comparator across four groups; count once. | S16: See source and specimen-specific notes | U16: 2011 | V16: 46 | W16: Bibliography/title audit; primary details not recovered | X16: Tables 1–3; journal pp. 3957–3959 | Y16: https://doi.org/10.1016/j.conbuildmat.2011.04.028 | Z16: 10.1016/j.conbuildmat.2011.04.028
A17: R027 | B17: Carvelli, V., Pisani, M. A., & Poggi, C. (2010) | C17: Slab experimental report | D17: Fatigue / moving load | E17: 4 | F17: full-scale deck specimens | G17: =COUNTIFS(Specimens!$B$7:$B$76,A17) -> 0 | H17: GFRP concrete deck slab fatigue experiments; inspect relation to 2006/other moving-load reports. | I17: Not recovered | J17: Not recovered | K17: Not recovered | L17: GFRP | M17: Moving concentrated loads simulated by two hydraulic jacks; subsequent static loading to failure | N17: See cited source; no quantitative result extracted | R17: Not a continuously rolling tyre test. No individual cycles or residual capacities obtained; do not treat subsequent static failure as fatigue failure. | S17: Qualitative moving-load and residual-static evidence | U17: 2010 | V17: 4 | W17: Original abstract on author paper record | X17: Abstract | Y17: https://www.sciencedirect.com/science/article/pii/S1359836810000910 | Z17: 10.1016/j.compositesb.2010.06.006
A18: R034 | B18: El-Gamal, S. (2005) | C18: Slab experimental report | D18: Punching / CMA | F18: Count not recovered | G18: =COUNTIFS(Specimens!$B$7:$B$76,A18) -> 0 | H18: Thesis; potential overlap with El-Gamal et al. 2005 and other Sherbrooke laboratory papers. | I18: Not recovered | J18: Not recovered | K18: Not recovered | L18: Not recovered | M18: Not recovered | N18: See cited source; no quantitative result extracted | Q18: El-Gamal thesis / 2005 article | R18: Thesis; potential overlap with El-Gamal et al. 2005 and other Sherbrooke laboratory papers. | S18: Additional specimen geometry, materials and response tables need primary-source extraction | U18: 2005 | W18: Bibliography/title audit; primary details not recovered | X18: Manuscript bibliography
A19: R035 | B19: El-Gamal, S., El-Salakawy, E., & Benmokrane, B. (2005) | C19: Slab experimental report | D19: Punching / CMA | E19: 6 | F19: Publication-reported specimens/units; do not sum across related reports | G19: =COUNTIFS(Specimens!$B$7:$B$76,A19) -> 0 | H19: Restrained bridge deck panels | I19: 3000 × 2500 × 200 mm; span2000mm; patch600×250mm | J19: Not recovered | K19: Not recovered | L19: Not recovered | M19: Not recovered | N19: See cited source; no quantitative result extracted | O19: 5 | P19: 1 | Q19: El-Gamal thesis / 2005 article | R19: Potential overlapping thesis El-Gamal2005; legacy G-S2/C-S2 in Elgabbas2016 not new tests. | S19: See source and specimen-specific notes | U19: 2005 | V19: 26 | W19: Primary institution abstract verified; two specimen response rows re-reported in Elgabbas2016 | X19: Manuscript bibliography | Y19: https://squ.elsevierpure.com/en/publications/behavior-of-concrete-bridge-deck-slabs-reinforced-with-fiber-rein/
A20: R036 | B20: El-Ragaby, A., & El-Salakawy, E. F. (2011) | C20: Slab experimental report | D20: Environmental-fatigue | E20: 4 | F20: large-scale GFRP deck slabs | G20: =COUNTIFS(Specimens!$B$7:$B$76,A20) -> 0 | H20: Deck experiments under severe environmental and repeated-load conditions; independent programs/specimens need source-level audit. | I20: Not recovered | J20: Not recovered | K20: Not recovered | L20: GFRP bars | M20: 3,000,000 sinusoidal fatigue cycles combined with 100 freeze-thaw cycles or one month continuous cold exposure | N20: See cited source; no quantitative result extracted | R20: Do not label 3M as failure life. Abstract reports satisfactory post-conditioning behavior. | S20: Environmental-fatigue program evidence; exact specimen geometry, load, temperature, identities unavailable | U20: 2011 | W20: Publisher primary abstract | X20: Publisher abstract; original article pp.1-20 | Y20: https://www.concrete.org/publications/internationalconcreteabstractsportal.aspx?i=51682472&m=details | Z20: 10.14359/51682472
A21: R038 | B21: El-Ragaby, A., El-Salakawy, E., & Benmokrane, B. (2003) | C21: Field report | D21: Wotton field | F21: Count not recovered | G21: =COUNTIFS(Specimens!$B$7:$B$76,A21) -> 0 | H21: Primary Wotton Bridge report; proof/truck loading, not failure test. | I21: Not recovered | J21: Not recovered | K21: Not recovered | L21: GFRP/CFRP per manuscript citation | M21: Not recovered | N21: See cited source; no quantitative result extracted | R21: Do not populate dimensions, proof-load or measured response from unidentified Wotton reports. | S21: Field source register only | U21: 2003 | W21: Bibliographic record in supplied manuscript only; primary text not recovered | X21: Manuscript bibliography
A22: R039 | B22: El-Ragaby, A., El-Salakawy, E., & Benmokrane, B. (2007b) | C22: Slab experimental report | D22: Fatigue life | E22: 5 | F22: full-scale slabs reported by reproduced original abstract | G22: =COUNTIFS(Specimens!$B$7:$B$76,A22) -> 0 | H22: Primary GFRP deck fatigue experimental program; companion 2007a reuses evidence. | I22: Not recovered | J22: Not recovered | K22: Not recovered | L22: GFRP and steel | M22: Concentrated, accelerated variable-amplitude cyclic loading until failure | N22: See cited source; no quantitative result extracted | Q22: El-Ragaby 2007 companions | R22: Five is publication-level count, not additive to six in 2007a. Recovered primary full text required to resolve identity. | S22: Program count requires primary full-text confirmation; no numerical validation rows | U22: 2007 | V22: 7 | W22: Original abstract reproduced in linked-paper preview; primary page inaccessible | X22: Original abstract reproduced in References preview of Noel and Soudki (2014) | Y22: https://ascelibrary.org/doi/10.1061/%28ASCE%291090-0268%282007%2911%3A3%28258%29 | Z22: 10.1061/(ASCE)1090-0268(2007)11:3(258)
A23: R040 | B23: El-Salakawy, E., & Benmokrane, B. (2004) | C23: Slab experimental report | D23: Serviceability | E23: 10 | F23: Publication-reported specimens/units; do not sum across related reports | G23: =COUNTIFS(Specimens!$B$7:$B$76,A23) -> 0 | H23: One-way slab strips under four-point bending | I23: 3100 × 1000 × 200 mm; simply supported clear span 2500 mm; shear span 1000 mm | J23: Not recovered | K23: Not recovered | L23: Not recovered | M23: Not recovered | N23: See cited source; no quantitative result extracted | O23: 8 | P23: 2 | Q23: El-Salakawy2004 / El-Sayed2005b possible overlap | R23: Ten full-size one-way slabs 3100x1000x200 mm per ACI abstract; distinguish one-way test idealization from restrained two-way deck. | S23: See source and specimen-specific notes | U23: 2004 | W23: Primary publisher abstract verified; specimen tables unavailable | X23: Manuscript bibliography | Y23: https://www.concrete.org/publications/internationalconcreteabstractsportal.aspx?ID=13395&m=details | Z23: 10.14359/13395
A24: R041 | B24: El-Salakawy, E., Benmokrane, B., El-Ragaby, A., & Nadeau, D. (2005) | C24: Field report | D24: Cookshire-Eaton field | E24: 1 | F24: field bridge with GFRP and galvanized-steel spans | G24: =COUNTIFS(Specimens!$B$7:$B$76,A24) -> 2 | H24: Primary field bridge investigation; proof-load/service response. | I24: thickness 200 mm | J24: Not recovered | K24: Not recovered | L24: GFRP; galvanized steel | M24: Not recovered | N24: Named units and measured response records extracted; see Test Results | R24: Primary field bridge investigation; proof-load/service response. | S24: Field serviceability only; same bridge paired spans | U24: 2005 | V24: 17 | W24: Author-uploaded full text | X24: Table1/p.471; Fig2/pp.471-472; field results pp.473-475 | Y24: https://ascelibrary.org/doi/10.1061/%28ASCE%291090-0268%282005%299%3A6%28470%29 | Z24: 10.1061/(ASCE)1090-0268(2005)9:6(470)
A25: R043 | B25: El-Sayed, A., El-Salakawy, E., & Benmokrane, B. (2005b) | C25: Slab experimental report | D25: One-way shear | E25: 8 | F25: Publication-reported specimens/units; do not sum across related reports | G25: =COUNTIFS(Specimens!$B$7:$B$76,A25) -> 0 | H25: One-way slabs | I25: 3100×1000×200mm | J25: Not recovered | K25: Not recovered | L25: Not recovered | M25: Not recovered | N25: See cited source; no quantitative result extracted | O25: 8 | Q25: El-Salakawy2004 / El-Sayed2005b possible overlap | R25: Very likely reanalysis of8FRP slabs from El-Salakawy2004(10=8FRP+2steel):identical geometry/type counts and shared authors. Flag possible overlap; do not assume18 independent slabs. | S25: See source and specimen-specific notes | U25: 2005 | W25: Primary author abstract verified; full table unavailable | X25: Manuscript bibliography | Y25: https://ascelibrary.com/doi/abs/10.1061/%28ASCE%291090-0268%282005%299%3A2%28147%29 | Z25: 10.1061/(ASCE)1090-0268(2005)9:2(147)
A26: R044 | B26: Elgabbas, F., Ahmed, E., & Benmokrane, B. (2016) | C26: Slab experimental report | D26: Punching / CMA | E26: 7 | F26: Publication-reported specimens/units; do not sum across related reports | G26: =COUNTIFS(Specimens!$B$7:$B$76,A26) -> 7 | H26: Restrained bridge-deck panels plus one unrestrained comparator | I26: length 3000 mm; width 2500 mm; thickness 200 mm; slab span 2000 mm | J26: Edge restrained; Unrestrained | K26: Not recovered | L26: Steel; BFRP | M26: Single central patch; monotonic | N26: Extracted failure loads 436.4–739.6 kN. Reported outcomes: Punching shear | O26: 6 | P26: 1 | R26: G-S2 and C-S2 in Table 3 are El-Gamal2005 legacy comparison specimens; not additional Elgabbas2016 specimens. | S26: See source and specimen-specific notes | U26: 2016 | V26: 31 | W26: User-supplied original journal PDF; also author full text | X26: Tables 1–3; PDF pp. 4, 5, 9 | Y26: https://doi.org/10.1061/(ASCE)BE.1943-5592.0000892 | Z26: 10.1061/(ASCE)BE.1943-5592.0000892
A27: R048 | B27: Gao, C., Tauskela, L., & Fam, A. (2024) | C27: Slab experimental report | D27: Rolling / pulsating fatigue | E27: 1 | F27: physical bridge deck with two compared GFRP test sections | G27: =COUNTIFS(Specimens!$B$7:$B$76,A27) -> 2 | H27: Direct full-scale GFRP deck comparison under different fatigue loading paths. | I27: length 15240 mm; width 3890 mm | J27: Not recovered | K27: Not recovered | L27: GFRP | M27: Rolling load; Fixed-point pulsating load | N27: Reported outcomes: No fatigue failure reported in accessible abstract; stopped cycle count, not Nf | R27: Stiffness-loss percentages reported in abstract (71% rolling and 54% pulsating) should not be mislabeled as residual k/k0. R/P equivalence is metric- and protocol-specific, not universal traffic conversion. | S27: Same-bridge paired loading-mode evidence, not two independent bridge specimens | U27: 2024 | W27: Original abstract on author paper record | X27: Abstract | Y27: https://ascelibrary.org/doi/10.1061/JCCOF2.CCENG-4608 | Z27: 10.1061/JCCOF2.CCENG-4608
A28: R055 | B28: Ju, M., Oh, H., & Sim, J. (2017) | C28: Slab experimental report | D28: Variable-amplitude fatigue | F28: Count not recovered | G28: =COUNTIFS(Specimens!$B$7:$B$76,A28) -> 0 | H28: CFRP-reinforced deck slab cyclic experiments; distinguish tested variable amplitude from validated Miner law. | I28: Not recovered | J28: Not recovered | K28: Not recovered | L28: CFRP | M28: Variable-amplitude cyclic loading; equivalent-cycle indirect fatigue assessment | N28: See cited source; no quantitative result extracted | R28: Abstract explicitly states failure cycle count unknown. Equivalent cycles and observed fatigue failure life must not be conflated. | S28: Qualitative variable-amplitude/indirect-life evidence | U28: 2017 | W28: Publisher primary abstract | X28: Abstract | Y28: https://link.springer.com/article/10.1007/s12205-016-1494-1 | Z28: 10.1007/s12205-016-1494-1
A29: R058 | B29: Mahroug, M., Ashour, A. F., & Lam, D. (2014) | C29: Slab experimental report | D29: Serviceability / continuous slabs | F29: Count not recovered | G29: =COUNTIFS(Specimens!$B$7:$B$76,A29) -> 0 | H29: Continuous BFRP concrete slabs; generic slab laboratory evidence, not full bridge-system restraint. | I29: Not recovered | J29: Not recovered | K29: Not recovered | L29: Not recovered | M29: Not recovered | N29: See cited source; no quantitative result extracted | R29: Continuous BFRP concrete slabs; generic slab laboratory evidence, not full bridge-system restraint. | S29: Additional specimen geometry, materials and response tables need primary-source extraction | U29: 2014 | W29: Bibliography/title audit; primary details not recovered | X29: Manuscript bibliography
A30: R060 | B30: Michaluk, C. R., Rizkalla, S. H., Tadros, G., and Benmokrane, B. (1998) | C30: Slab experimental report | D30: One-way flexure | E30: 8 | F30: Publication-reported specimens/units; do not sum across related reports | G30: =COUNTIFS(Specimens!$B$7:$B$76,A30) -> 8 | H30: Simply supported one-way slabs | I30: 3500×1000×150/200mm; clear span3000mm; cover38mm | J30: Simply supported | K30: Not recovered | L30: Steel; GFRP; CFRP | M30: Four-point bending; full-width line supports | N30: Extracted failure loads 47.1–259.1 kN. Reported outcomes: Yielding then concrete crushing, FRP rupture, Shear of GFRP at major crack, Bond slip | O30: 6 | P30: 2 | R30: Eight one-way slabs with glass, carbon and conventional steel reinforcement per ACI primary abstract; correct pages353–365 (manuscript145–157 is wrong). | S30: See source and specimen-specific notes | U30: 1998 | W30: Full original article deposited on Academia; Tables1–4 pp355,358 | X30: Tables1–2 p355; Tables3–4 p358 | Y30: https://www.concrete.org/publications/internationalconcreteabstractsportal.aspx?id=552&m=details | Z30: 10.14359/552
A31: R066 | B31: Rossini, M., Cadenazzi, T., Nolan, S., & Nanni, A. (2019) | C31: Field report | D31: Halls River field | F31: Count not recovered | G31: =COUNTIFS(Specimens!$B$7:$B$76,A31) -> 0 | H31: Field demonstration / construction report; no deck punching failure tests. | I31: Not recovered | J31: Not recovered | K31: Not recovered | L31: Not recovered | M31: Not recovered | N31: See cited source; no quantitative result extracted | R31: Field demonstration / construction report; no deck punching failure tests. | S31: Additional specimen geometry, materials and response tables need primary-source extraction | U31: 2019 | W31: Bibliography/title audit; primary details not recovered | X31: Manuscript bibliography
A32: R073 | B32: Zheng, Y., Sun, C., Deng, T., et al. (2014) | C32: Slab experimental report | D32: Punching / CMA | F32: Count not recovered | G32: =COUNTIFS(Specimens!$B$7:$B$76,A32) -> 0 | H32: One-third-scale restrained GFRP deck experiments and arching model; same investigator group as 2012, independence must be reported cautiously. | I32: one-third | J32: Not recovered | K32: concrete | L32: GFRP | M32: static concentrated loading | N32: Higher lateral restraint stiffness increased punching strength and reduced FRP strain; transition from flexural punching to shear punching reported. | Q32: Zheng 2012 / 2014 potential reuse | R32: Combines current tests and literature tests for model assessment. Check specimen overlap with Zheng2012 and later NLFEA papers before aggregation. | S32: Exact primary specimen identifiers, counts, dimensions, material values and individual loads require full text. | U32: 2014 | W32: Primary publisher abstract; full text restricted | X32: Publisher abstract | Y32: https://link.springer.com/article/10.1007/s13369-014-1450-7 | Z32: 10.1007/s13369-014-1450-7
A33: R074 | B33: Zheng, Y., Taylor, S. E., Zhou, L., Grattan, S., Sonebi, M., & Liao, J. (2024) | C33: Field report | D33: Thompson Bridge field | E33: 6 | F33: Publication-reported specimens/units; do not sum across related reports | G33: =COUNTIFS(Specimens!$B$7:$B$76,A33) -> 6 | H33: Six proof-loaded panels: four BFRP and two steel. All sustained 400 kN without failure. Separate from SCC simulation and lab programs. | I33: thickness 160 mm; slab span 1400–1600 mm | J33: Integral skew bridge; W-beam support and continuity; restraint stiffness not quantified | K33: SCC | L33: BFRP/steel | M33: static central circular 300-mm bearing contact; service tests then maximum 400 kN | N33: No observed ultimate failure through 400 kN. Recorded strength is a right-censored lower bound, not an ultimate load. | O33: 4 | P33: 2 | Q33: Thompson Bridge field panels | R33: One Thompson Bridge, six loading locations. Do not count each panel as independent bridge or duplicate field data from Zhou2018 FE paper. | S33: Individual effective depths, clear cover and bar spacings not verified in extracted material; preserve as unknown. | U33: 2024 | V33: 11 | W33: Primary open-access published PDF text; tables extracted | X33: Sections 3.1-3.4; Tables 2-3, printed pp.4-6 (PDF pp.5-7) | Y33: https://pureadmin.qub.ac.uk/ws/portalfiles/portal/559489876/1-s2.0-S2214509524001943-main.pdf | Z33: 10.1016/j.cscm.2024.e03043
A34: R075 | B34: Zheng, Y., Yu, G.Y., & Pan, Y. (2012) | C34: Slab experimental report | D34: Punching / CMA | F34: Count not recovered | G34: =COUNTIFS(Specimens!$B$7:$B$76,A34) -> 0 | H34: GFRP deck laboratory experiments and ultimate-strength model; audit reuse in 2014 and numerical followups. | I34: one-third | J34: Not recovered | K34: Not recovered | L34: GFRP | M34: static bridge-deck tests | N34: See cited source; no quantitative result extracted | Q34: Zheng 2012 / 2014 potential reuse | R34: Potential companion/reanalysis linkage with Zheng2014 and Zheng2013 numerical papers; unresolved. | S34: Exact specimen IDs/count and individual geometries, strengths, reinforcement properties and loads unavailable. | U34: 2012 | V34: 39 | W34: Primary publisher metadata/section preview; full text unavailable | X34: Publisher indexed abstract and section preview | Y34: https://www.sciencedirect.com/science/article/abs/pii/S0950061811005228 | Z34: 10.1016/j.conbuildmat.2011.09.002
A35: R077 | B35: Zheng, Y., Zhou, L., Taylor, S.E., & Ma, H. (2019) | C35: Slab experimental report | D35: Serviceability | F35: Count not recovered | G35: =COUNTIFS(Specimens!$B$7:$B$76,A35) -> 0 | H35: BFRP HVFA-SCC one-way slab study with NC controls. Earlier author manuscript identifies this as a Fig.6 source program; exact plotted specimen and concrete matrix remain unverified. | I35: full | J35: Not recovered | K35: HVFA-SCC; normal concrete control | L35: BFRP and steel control | M35: four-point bending | N35: Assesses deflection, cracking load, crack spacing and crack-width models; proposes a revised maximum-crack-width relation. | R35: BFRP HVFA-SCC one-way slab study with NC controls. Earlier author manuscript identifies this as a Fig.6 source program; exact plotted specimen and concrete matrix remain unverified. | S35: Exact count, specimen IDs, geometries, material values, response records, curve identifier and calibration/validation division. | U35: 2019 | V35: 49 | W35: Primary author repository metadata and abstract; full text not available | X35: Author institutional repository abstract | Y35: https://pure.qub.ac.uk/en/publications/serviceability-of-one-way-high-volume-fly-ash-self-compacting-con/ | Z35: 10.1016/j.conbuildmat.2019.05.044
A36: R078 | B36: Zheng, Y., Zhou, L.Z., Xia, L.P., et al. (2018) | C36: Slab experimental report | D36: Punching / CMA | E36: 6 | F36: Publication-reported specimens/units; do not sum across related reports | G36: =COUNTIFS(Specimens!$B$7:$B$76,A36) -> 0 | H36: SCC BFRP deck laboratory experiments; must not be merged with Thompson field proof panels. | I36: half | J36: Not recovered | K36: SCC | L36: BFRP | M36: single central concentrated load to failure | N36: All six half-scale deck specimens reportedly failed in punching. | R36: Laboratory study extends Thompson Bridge concept; six laboratory slabs are not the six field panels in Zheng2024. | S36: Individual specimen IDs, dimensions, FRP properties, restraint and ultimate loads require original full text. | U36: 2018 | V36: 42 | W36: Study abstract only; no individual records extracted | X36: Author abstract reproduced in author publication listing; publisher metadata verified | Y36: https://www.sciencedirect.com/science/article/pii/S0141029618300920 | Z36: 10.1016/j.engstruct.2018.05.105
A37: R080 | B37: Zhou, L., Dong, P., Zheng, Y., Song, G., & Wang, X. (2020) | C37: Slab experimental report | D37: Serviceability | E37: 11 | F37: Publication-reported specimens/units; do not sum across related reports | G37: =COUNTIFS(Specimens!$B$7:$B$76,A37) -> 0 | H37: Eleven full-scale one-way HVFA-SCC slabs with NC controls; online2020, issue2021. Earlier author manuscript identifies the GFRP source program; plotted specimen and matrix remain unverified. | I37: full | J37: Not recovered | K37: HVFA-SCC and NC control | L37: GFRP and control reinforcement | M37: four-point bending | N37: 19-mm GFRP bars enlarged maximum cracks in tested HVFA-SCC slabs; similar broad structural response to NC control; model comparison includes cracking load, capacity, crack width/spacing and deflection. | Q37: Zhou online 2020 / issue 2021 | R37: Eleven full-scale one-way HVFA-SCC slabs with NC controls; online2020, issue2021. Earlier author manuscript identifies the GFRP source program; plotted specimen and matrix remain unverified. | S37: Exact specimen IDs, individual geometries/materials and response records; author correspondence or primary PDF needed to resolve current Figure6. | T37: 2020-09-09 | U37: 2021 | W37: Primary publisher metadata and abstract; full text restricted | X37: Publisher abstract; Volume 1 Issue 1 (2021), pp. 160-182 | Y37: https://www.eurekaselect.com/article/109839 | Z37: 10.2174/2210298101666200909160857

Sheet Model Benchmark
A2: Elgabbas 2016 published punching-load ratios
A3: Six BFRP slabs from one laboratory. Published ratios are rounded; five restrained slabs and one unrestrained slab remain distinct.
A6: Unit ID | B6: Reference ID | C6: Source specimen | D6: Lateral restraint | E6: Measured ultimate load (kN) | F6: Published measured / predicted: CSA S806-12 | G6: Published measured / predicted: ACI440.1R-06 | H6: Reciprocal predicted / measured: CSA | I6: Reciprocal predicted / measured: ACI | J6: Interpretation | K6: Source locator | L6: Source URL
A7: R044-S2-B | B7: R044 | C7: S2-B | D7: Edge restrained | E7: 548.3 | F7: 0.92 | G7: 1.53 | H7: =1/F7 -> 1.0869565 | I7: =1/G7 -> 0.65359477 | J7: Published ratios rounded to 2 decimal places. No model equation was independently recalculated. | K7: Table 3 | L7: https://doi.org/10.1061/(ASCE)BE.1943-5592.0000892
A8: R044-S3-B | B8: R044 | C8: S3-B | D8: Edge restrained | E8: 664.6 | F8: 1.13 | G8: 1.86 | H8: =1/F8 -> 0.88495575 | I8: =1/G8 -> 0.53763441 | J8: Published ratios rounded to 2 decimal places. No model equation was independently recalculated. | K8: Table 3 | L8: https://doi.org/10.1061/(ASCE)BE.1943-5592.0000892
A9: R044-S4-B | B9: R044 | C9: S4-B | D9: Edge restrained | E9: 565.9 | F9: 1 | G9: 1.64 | H9: =1/F9 -> 1 | I9: =1/G9 -> 0.6097561 | J9: Published ratios rounded to 2 decimal places. No model equation was independently recalculated. | K9: Table 3 | L9: https://doi.org/10.1061/(ASCE)BE.1943-5592.0000892
A10: R044-S5-B | B10: R044 | C10: S5-B | D10: Edge restrained | E10: 716.4 | F10: 1.06 | G10: 1.67 | H10: =1/F10 -> 0.94339623 | I10: =1/G10 -> 0.5988024 | J10: Published ratios rounded to 2 decimal places. No model equation was independently recalculated. | K10: Table 3 | L10: https://doi.org/10.1061/(ASCE)BE.1943-5592.0000892
A11: R044-S6-B | B11: R044 | C11: S6-B | D11: Edge restrained | E11: 575.8 | F11: 1.22 | G11: 2.23 | H11: =1/F11 -> 0.81967213 | I11: =1/G11 -> 0.44843049 | J11: Published ratios rounded to 2 decimal places. No model equation was independently recalculated. | K11: Table 3 | L11: https://doi.org/10.1061/(ASCE)BE.1943-5592.0000892
A12: R044-S7-B | B12: R044 | C12: S7-B | D12: Unrestrained | E12: 436.4 | F12: 0.93 | G12: 1.69 | H12: =1/F12 -> 1.0752688 | I12: =1/G12 -> 0.59171598 | J12: Published ratios rounded to 2 decimal places. No model equation was independently recalculated. | K12: Table 3 | L12: https://doi.org/10.1061/(ASCE)BE.1943-5592.0000892
A16: Model | B16: Restraint stratum | C16: n | D16: Mean measured / predicted | E16: Sample COV | F16: Prediction exceeds test: fraction
A17: CSA S806-12 | B17: Restrained S2–S6 | C17: =COUNT(F7:F11) -> 5 | D17: =AVERAGE(F7:F11) -> 1.066 | E17: =_xludf.STDEV.S(F7:F11)/AVERAGE(F7:F11) -> #NAME? | F17: =COUNTIFS(F7:F11,"<1")/COUNT(F7:F11) -> 0.2
A18: ACI440.1R-06 | B18: Restrained S2–S6 | C18: =COUNT(G7:G11) -> 5 | D18: =AVERAGE(G7:G11) -> 1.786 | E18: =_xludf.STDEV.S(G7:G11)/AVERAGE(G7:G11) -> #NAME? | F18: =COUNTIFS(G7:G11,"<1")/COUNT(G7:G11) -> 0
A19: CSA S806-12 | B19: Unrestrained S7 | C19: =COUNT(F12:F12) -> 1 | D19: =AVERAGE(F12:F12) -> 0.93 | E19: n.a. | F19: =COUNTIFS(F12:F12,"<1")/COUNT(F12:F12) -> 1
A20: ACI440.1R-06 | B20: Unrestrained S7 | C20: =COUNT(G12:G12) -> 1 | D20: =AVERAGE(G12:G12) -> 1.69 | E20: n.a. | F20: =COUNTIFS(G12:G12,"<1")/COUNT(G12:G12) -> 0

Sheet Service Benchmark
A2: Al-Sunna 2012 published deflection-model ratios
A3: Six FRP slab series, each with a/b replicates. Published ratios are series-level comparisons at two load states.
A6: Comparison ID | B6: Reference ID | C6: Source series | D6: Load state | E6: Prediction model | F6: Published predicted / measured deflection | G6: Record definition | H6: Source locator | I6: Source URL
A7: R012-SC1-Service-ACI 440.1R-06 | B7: R012 | C7: SC1 | D7: Service | E7: ACI 440.1R-06 | F7: 1.08 | G7: Published SERIES-LEVEL ratio. Do not replicate to specimen a and b, or describe as raw specimen-level reanalysis. | H7: Table5; accepted manuscript p.16 | I7: https://eprints.whiterose.ac.uk/id/eprint/85515/1/Deflection%20behaviour%20of%20FRP%20reinforced%20concrete%20beams%20and%20slabs-%20An%20experimental%20investigation.pdf
A8: R012-SC2-Service-ACI 440.1R-06 | B8: R012 | C8: SC2 | D8: Service | E8: ACI 440.1R-06 | F8: 0.61 | G8: Published SERIES-LEVEL ratio. Do not replicate to specimen a and b, or describe as raw specimen-level reanalysis. | H8: Table5; accepted manuscript p.16 | I8: https://eprints.whiterose.ac.uk/id/eprint/85515/1/Deflection%20behaviour%20of%20FRP%20reinforced%20concrete%20beams%20and%20slabs-%20An%20experimental%20investigation.pdf
A9: R012-SC3-Service-ACI 440.1R-06 | B9: R012 | C9: SC3 | D9: Service | E9: ACI 440.1R-06 | F9: 0.71 | G9: Published SERIES-LEVEL ratio. Do not replicate to specimen a and b, or describe as raw specimen-level reanalysis. | H9: Table5; accepted manuscript p.16 | I9: https://eprints.whiterose.ac.uk/id/eprint/85515/1/Deflection%20behaviour%20of%20FRP%20reinforced%20concrete%20beams%20and%20slabs-%20An%20experimental%20investigation.pdf
A10: R012-SG1-Service-ACI 440.1R-06 | B10: R012 | C10: SG1 | D10: Service | E10: ACI 440.1R-06 | F10: 1.18 | G10: Published SERIES-LEVEL ratio. Do not replicate to specimen a and b, or describe as raw specimen-level reanalysis. | H10: Table5; accepted manuscript p.16 | I10: https://eprints.whiterose.ac.uk/id/eprint/85515/1/Deflection%20behaviour%20of%20FRP%20reinforced%20concrete%20beams%20and%20slabs-%20An%20experimental%20investigation.pdf
A11: R012-SG2-Service-ACI 440.1R-06 | B11: R012 | C11: SG2 | D11: Service | E11: ACI 440.1R-06 | F11: 0.66 | G11: Published SERIES-LEVEL ratio. Do not replicate to specimen a and b, or describe as raw specimen-level reanalysis. | H11: Table5; accepted manuscript p.16 | I11: https://eprints.whiterose.ac.uk/id/eprint/85515/1/Deflection%20behaviour%20of%20FRP%20reinforced%20concrete%20beams%20and%20slabs-%20An%20experimental%20investigation.pdf
A12: R012-SG3-Service-ACI 440.1R-06 | B12: R012 | C12: SG3 | D12: Service | E12: ACI 440.1R-06 | F12: 0.65 | G12: Published SERIES-LEVEL ratio. Do not replicate to specimen a and b, or describe as raw specimen-level reanalysis. | H12: Table5; accepted manuscript p.16 | I12: https://eprints.whiterose.ac.uk/id/eprint/85515/1/Deflection%20behaviour%20of%20FRP%20reinforced%20concrete%20beams%20and%20slabs-%20An%20experimental%20investigation.pdf
A13: R012-SC1-Service-Benmokrane et al.1996 | B13: R012 | C13: SC1 | D13: Service | E13: Benmokrane et al.1996 | F13: 1.13 | G13: Published SERIES-LEVEL ratio. Do not replicate to specimen a and b, or describe as raw specimen-level reanalysis. | H13: Table5; accepted manuscript p.16 | I13: https://eprints.whiterose.ac.uk/id/eprint/85515/1/Deflection%20behaviour%20of%20FRP%20reinforced%20concrete%20beams%20and%20slabs-%20An%20experimental%20investigation.pdf
A14: R012-SC2-Service-Benmokrane et al.1996 | B14: R012 | C14: SC2 | D14: Service | E14: Benmokrane et al.1996 | F14: 1.05 | G14: Published SERIES-LEVEL ratio. Do not replicate to specimen a and b, or describe as raw specimen-level reanalysis. | H14: Table5; accepted manuscript p.16 | I14: https://eprints.whiterose.ac.uk/id/eprint/85515/1/Deflection%20behaviour%20of%20FRP%20reinforced%20concrete%20beams%20and%20slabs-%20An%20experimental%20investigation.pdf
A15: R012-SC3-Service-Benmokrane et al.1996 | B15: R012 | C15: SC3 | D15: Service | E15: Benmokrane et al.1996 | F15: 1.13 | G15: Published SERIES-LEVEL ratio. Do not replicate to specimen a and b, or describe as raw specimen-level reanalysis. | H15: Table5; accepted manuscript p.16 | I15: https://eprints.whiterose.ac.uk/id/eprint/85515/1/Deflection%20behaviour%20of%20FRP%20reinforced%20concrete%20beams%20and%20slabs-%20An%20experimental%20investigation.pdf
A16: R012-SG1-Service-Benmokrane et al.1996 | B16: R012 | C16: SG1 | D16: Service | E16: Benmokrane et al.1996 | F16: 1.1 | G16: Published SERIES-LEVEL ratio. Do not replicate to specimen a and b, or describe as raw specimen-level reanalysis. | H16: Table5; accepted manuscript p.16 | I16: https://eprints.whiterose.ac.uk/id/eprint/85515/1/Deflection%20behaviour%20of%20FRP%20reinforced%20concrete%20beams%20and%20slabs-%20An%20experimental%20investigation.pdf
A17: R012-SG2-Service-Benmokrane et al.1996 | B17: R012 | C17: SG2 | D17: Service | E17: Benmokrane et al.1996 | F17: 1.24 | G17: Published SERIES-LEVEL ratio. Do not replicate to specimen a and b, or describe as raw specimen-level reanalysis. | H17: Table5; accepted manuscript p.16 | I17: https://eprints.whiterose.ac.uk/id/eprint/85515/1/Deflection%20behaviour%20of%20FRP%20reinforced%20concrete%20beams%20and%20slabs-%20An%20experimental%20investigation.pdf
A18: R012-SG3-Service-Benmokrane et al.1996 | B18: R012 | C18: SG3 | D18: Service | E18: Benmokrane et al.1996 | F18: 1.42 | G18: Published SERIES-LEVEL ratio. Do not replicate to specimen a and b, or describe as raw specimen-level reanalysis. | H18: Table5; accepted manuscript p.16 | I18: https://eprints.whiterose.ac.uk/id/eprint/85515/1/Deflection%20behaviour%20of%20FRP%20reinforced%20concrete%20beams%20and%20slabs-%20An%20experimental%20investigation.pdf
... A42: R012-SG3-Ultimate-Eurocode2 / Bischoff | B42: R012 | C42: SG3 | D42: Ultimate | E42: Eurocode2 / Bischoff | F42: 0.86 | G42: Published SERIES-LEVEL ratio. Do not replicate to specimen a and b, or describe as raw specimen-level reanalysis. | H42: Table5; accepted manuscript p.16 | I42: https://eprints.whiterose.ac.uk/id/eprint/85515/1/Deflection%20behaviour%20of%20FRP%20reinforced%20concrete%20beams%20and%20slabs-%20An%20experimental%20investigation.pdf
A47: Model | B47: Load state | C47: Series n | D47: Mean predicted / measured | E47: Sample COV | F47: Underpredicted deflection fraction
A48: ACI 440.1R-06 | B48: Service | C48: =COUNT(F7:F12) -> 6 | D48: =AVERAGE(F7:F12) -> 0.815 | E48: =_xludf.STDEV.S(F7:F12)/AVERAGE(F7:F12) -> #NAME? | F48: =COUNTIFS(F7:F12,"<1")/COUNT(F7:F12) -> 0.66666667
A49: Benmokrane et al.1996 | B49: Service | C49: =COUNT(F13:F18) -> 6 | D49: =AVERAGE(F13:F18) -> 1.1783333 | E49: =_xludf.STDEV.S(F13:F18)/AVERAGE(F13:F18) -> #NAME? | F49: =COUNTIFS(F13:F18,"<1")/COUNT(F13:F18) -> 0
A50: Eurocode2 / Bischoff | B50: Service | C50: =COUNT(F19:F24) -> 6 | D50: =AVERAGE(F19:F24) -> 0.85 | E50: =_xludf.STDEV.S(F19:F24)/AVERAGE(F19:F24) -> #NAME? | F50: =COUNTIFS(F19:F24,"<1")/COUNT(F19:F24) -> 1
A51: ACI 440.1R-06 | B51: Ultimate | C51: =COUNT(F25:F30) -> 6 | D51: =AVERAGE(F25:F30) -> 0.83166667 | E51: =_xludf.STDEV.S(F25:F30)/AVERAGE(F25:F30) -> #NAME? | F51: =COUNTIFS(F25:F30,"<1")/COUNT(F25:F30) -> 1
A52: Benmokrane et al.1996 | B52: Ultimate | C52: =COUNT(F31:F36) -> 6 | D52: =AVERAGE(F31:F36) -> 1.02 | E52: =_xludf.STDEV.S(F31:F36)/AVERAGE(F31:F36) -> #NAME? | F52: =COUNTIFS(F31:F36,"<1")/COUNT(F31:F36) -> 0.16666667
A53: Eurocode2 / Bischoff | B53: Ultimate | C53: =COUNT(F37:F42) -> 6 | D53: =AVERAGE(F37:F42) -> 0.86333333 | E53: =_xludf.STDEV.S(F37:F42)/AVERAGE(F37:F42) -> #NAME? | F53: =COUNTIFS(F37:F42,"<1")/COUNT(F37:F42) -> 1

Sheet Specimens
A2: Named experimental units with geometry and material data
A3: Named records recovered from cited sources. Laboratory slabs, field panels and bridge test zones are identified separately.
A6: Unit ID | B6: Reference ID | C6: Source specimen / unit | D6: Record type | E6: Program / bridge ID | F6: Reinforcement | G6: Concrete | H6: Length (mm) | I6: Width (mm) | J6: Thickness h (mm) | K6: Effective depth d (mm) | L6: Span (mm) | M6: Shear span a (mm) | N6: a/d | O6: Concrete strength (MPa) | P6: Strength-test basis | Q6: Bar diameter (mm) | R6: Bar designation | S6: Bar spacing (mm) | T6: Reinforcement ratio (%) | U6: Reinforcement modulus (GPa) | V6: Bar strength (MPa) | W6: Bar-strength basis | X6: Bottom cover (mm) | Y6: Top cover (mm) | Z6: Contact length (mm) | AA6: Contact width (mm) | AB6: Contact diameter (mm) | AC6: Support / restraint | AD6: Loading | AE6: Failure / outcome | AF6: Data limitations and notes | AG6: Verification level | AH6: Source locator | AI6: Source URL
A7: R044-S1-S | B7: R044 | C7: S1-S | D7: Laboratory specimen | E7: ELG2016 | F7: Steel | H7: 3000 | I7: 2500 | J7: 200 | L7: 2000 | O7: 48.81 | P7: Compression-test basis not extracted; no cube-cylinder conversion | R7: 15M | S7: 150 | T7: 0.8 | U7: 200 | V7: 450 | W7: Steel yield strength | X7: 25 | Y7: 30 | Z7: 600 | AA7: 250 | AC7: Edge restrained | AD7: Single central patch; monotonic | AE7: Punching shear | AF7: Dash in Table3; text states not cracked at service load. Not coded as measured zero. Steel yield strength | AG7: Primary table transcription | AH7: Tables 1–3 (PDF pp. 4, 5, 9) | AI7: https://doi.org/10.1061/(ASCE)BE.1943-5592.0000892
A8: R044-S2-B | B8: R044 | C8: S2-B | D8: Laboratory specimen | E8: ELG2016 | F8: BFRP | H8: 3000 | I8: 2500 | J8: 200 | L8: 2000 | O8: 48.81 | P8: Compression-test basis not extracted; no cube-cylinder conversion | Q8: 16 | S8: 150 | T8: 0.8 | U8: 64.8 | V8: 1724 | W8: As reported; FRP rupture versus steel yield must be retained | X8: 25 | Y8: 30 | Z8: 600 | AA8: 250 | AC8: Edge restrained | AD8: Single central patch; monotonic | AE8: Punching shear | AG8: Primary table transcription | AH8: Tables 1–3 (PDF pp. 4, 5, 9) | AI8: https://doi.org/10.1061/(ASCE)BE.1943-5592.0000892
A9: R044-S3-B | B9: R044 | C9: S3-B | D9: Laboratory specimen | E9: ELG2016 | F9: BFRP | H9: 3000 | I9: 2500 | J9: 200 | L9: 2000 | O9: 42.2 | P9: Compression-test basis not extracted; no cube-cylinder conversion | Q9: 12 | S9: 85 | T9: 0.79 | U9: 69.3 | V9: 1760 | W9: As reported; FRP rupture versus steel yield must be retained | X9: 25 | Y9: 30 | Z9: 600 | AA9: 250 | AC9: Edge restrained | AD9: Single central patch; monotonic | AE9: Punching shear | AF9: Dash in Table3; text states not cracked at service load. Not coded as measured zero. | AG9: Primary table transcription | AH9: Tables 1–3 (PDF pp. 4, 5, 9) | AI9: https://doi.org/10.1061/(ASCE)BE.1943-5592.0000892
A10: R044-S4-B | B10: R044 | C10: S4-B | D10: Laboratory specimen | E10: ELG2016 | F10: BFRP | H10: 3000 | I10: 2500 | J10: 200 | L10: 2000 | O10: 42.2 | P10: Compression-test basis not extracted; no cube-cylinder conversion | Q10: 16 | S10: 150 | T10: 0.8 | U10: 64.8 | V10: 1724 | W10: As reported; FRP rupture versus steel yield must be retained | X10: 25 | Y10: 30 | Z10: 600 | AA10: 250 | AC10: Edge restrained | AD10: Single central patch; monotonic | AE10: Punching shear | AF10: No top reinforcement. Dash in Table3; text states not cracked at service load. Not coded as measured zero. | AG10: Primary table transcription | AH10: Tables 1–3 (PDF pp. 4, 5, 9) | AI10: https://doi.org/10.1061/(ASCE)BE.1943-5592.0000892
A11: R044-S5-B | B11: R044 | C11: S5-B | D11: Laboratory specimen | E11: ELG2016 | F11: BFRP | H11: 3000 | I11: 2500 | J11: 200 | L11: 2000 | O11: 47.9 | P11: Compression-test basis not extracted; no cube-cylinder conversion | Q11: 16 | S11: 100 | T11: 1.2 | U11: 64.8 | V11: 1724 | W11: As reported; FRP rupture versus steel yield must be retained | X11: 25 | Y11: 30 | Z11: 600 | AA11: 250 | AC11: Edge restrained | AD11: Single central patch; monotonic | AE11: Punching shear | AG11: Primary table transcription | AH11: Tables 1–3 (PDF pp. 4, 5, 9) | AI11: https://doi.org/10.1061/(ASCE)BE.1943-5592.0000892
A12: R044-S6-B | B12: R044 | C12: S6-B | D12: Laboratory specimen | E12: ELG2016 | F12: BFRP | H12: 3000 | I12: 2500 | J12: 200 | L12: 2000 | O12: 47.9 | P12: Compression-test basis not extracted; no cube-cylinder conversion | Q12: 16 | S12: 300 | T12: 0.4 | U12: 64.8 | V12: 1724 | W12: As reported; FRP rupture versus steel yield must be retained | X12: 25 | Y12: 30 | Z12: 600 | AA12: 250 | AC12: Edge restrained | AD12: Single central patch; monotonic | AE12: Punching shear | AF12: Pre-existing cracks possible; crack-width LVDT malfunctioned after 220 kN; ultimate crack width is missing, not zero. | AG12: Primary table transcription | AH12: Tables 1–3 (PDF pp. 4, 5, 9) | AI12: https://doi.org/10.1061/(ASCE)BE.1943-5592.0000892
A13: R044-S7-B | B13: R044 | C13: S7-B | D13: Laboratory specimen | E13: ELG2016 | F13: BFRP | H13: 3000 | I13: 2500 | J13: 200 | L13: 2000 | O13: 47.9 | P13: Compression-test basis not extracted; no cube-cylinder conversion | Q13: 16 | S13: 300 | T13: 0.4 | U13: 64.8 | V13: 1724 | W13: As reported; FRP rupture versus steel yield must be retained | X13: 25 | Y13: 30 | Z13: 600 | AA13: 250 | AC13: Unrestrained | AD13: Single central patch; monotonic | AE13: Punching shear | AF13: Dash in Table3; text states not cracked at service load. Not coded as measured zero. | AG13: Primary table transcription | AH13: Tables 1–3 (PDF pp. 4, 5, 9) | AI13: https://doi.org/10.1061/(ASCE)BE.1943-5592.0000892
A14: R025-G-200-N | B14: R025 | C14: G-200-N | D14: Laboratory specimen | E14: BOU2011 | F14: GFRP | H14: 3000 | I14: 2500 | J14: 200 | L14: 2000 | O14: 49.1 | P14: Compression-test basis not extracted; no cube-cylinder conversion | Q14: 19.1 | S14: 150 | T14: 1.2 | U14: 44.5 | V14: 637 | W14: As reported; FRP rupture versus steel yield must be retained | X14: 25 | Y14: 25 | Z14: 600 | AA14: 250 | AC14: Edge restrained | AD14: Single central patch; monotonic | AE14: Punching shear | AG14: Author-deposited primary full text, table transcription | AH14: Tables 1–3; journal pp. 3957–3959 | AI14: https://doi.org/10.1016/j.conbuildmat.2011.04.028
A15: R025-G-175-N | B15: R025 | C15: G-175-N | D15: Laboratory specimen | E15: BOU2011 | F15: GFRP | H15: 3000 | I15: 2500 | J15: 175 | L15: 2000 | O15: 35.2 | P15: Compression-test basis not extracted; no cube-cylinder conversion | Q15: 15.9 | S15: 115 | T15: 1.2 | U15: 41.6 | V15: 778 | W15: As reported; FRP rupture versus steel yield must be retained | X15: 25 | Y15: 25 | Z15: 600 | AA15: 250 | AC15: Edge restrained | AD15: Single central patch; monotonic | AE15: Punching shear | AG15: Author-deposited primary full text, table transcription | AH15: Tables 1–3; journal pp. 3957–3959 | AI15: https://doi.org/10.1016/j.conbuildmat.2011.04.028
A16: R025-G-150-N | B16: R025 | C16: G-150-N | D16: Laboratory specimen | E16: BOU2011 | F16: GFRP | H16: 3000 | I16: 2500 | J16: 150 | L16: 2000 | O16: 35.2 | P16: Compression-test basis not extracted; no cube-cylinder conversion | Q16: 15.9 | S16: 140 | T16: 1.2 | U16: 41.6 | V16: 778 | W16: As reported; FRP rupture versus steel yield must be retained | X16: 25 | Y16: 25 | Z16: 600 | AA16: 250 | AC16: Edge restrained | AD16: Single central patch; monotonic | AE16: Punching shear | AG16: Author-deposited primary full text, table transcription | AH16: Tables 1–3; journal pp. 3957–3959 | AI16: https://doi.org/10.1016/j.conbuildmat.2011.04.028
A17: R025-G-175-H | B17: R025 | C17: G-175-H | D17: Laboratory specimen | E17: BOU2011 | F17: GFRP | H17: 3000 | I17: 2500 | J17: 175 | L17: 2000 | O17: 64.8 | P17: Compression-test basis not extracted; no cube-cylinder conversion | Q17: 15.9 | S17: 115 | T17: 1.2 | U17: 41.6 | V17: 778 | W17: As reported; FRP rupture versus steel yield must be retained | X17: 25 | Y17: 25 | Z17: 600 | AA17: 250 | AC17: Edge restrained | AD17: Single central patch; monotonic | AE17: Punching shear | AG17: Author-deposited primary full text, table transcription | AH17: Tables 1–3; journal pp. 3957–3959 | AI17: https://doi.org/10.1016/j.conbuildmat.2011.04.028
A18: R025-G-175-N-0.7 | B18: R025 | C18: G-175-N-0.7 | D18: Laboratory specimen | E18: BOU2011 | F18: GFRP | H18: 3000 | I18: 2500 | J18: 175 | L18: 2000 | O18: 53.1 | P18: Compression-test basis not extracted; no cube-cylinder conversion | Q18: 15.9 | S18: 200 | T18: 0.7 | U18: 41.6 | V18: 778 | W18: As reported; FRP rupture versus steel yield must be retained | X18: 25 | Y18: 25 | Z18: 600 | AA18: 250 | AC18: Edge restrained | AD18: Single central patch; monotonic | AE18: Punching shear | AG18: Author-deposited primary full text, table transcription | AH18: Tables 1–3; journal pp. 3957–3959 | AI18: https://doi.org/10.1016/j.conbuildmat.2011.04.028
A19: R025-G-175-N-0.35 | B19: R025 | C19: G-175-N-0.35 | D19: Laboratory specimen | E19: BOU2011 | F19: GFRP | H19: 3000 | I19: 2500 | J19: 175 | L19: 2000 | O19: 53.1 | P19: Compression-test basis not extracted; no cube-cylinder conversion | Q19: 12.7 | S19: 255 | T19: 0.35 | U19: 41 | V19: 769 | W19: As reported; FRP rupture versus steel yield must be retained | X19: 25 | Y19: 25 | Z19: 600 | AA19: 250 | AC19: Edge restrained | AD19: Single central patch; monotonic | AE19: Punching shear | AG19: Author-deposited primary full text, table transcription | AH19: Tables 1–3; journal pp. 3957–3959 | AI19: https://doi.org/10.1016/j.conbuildmat.2011.04.028
A20: R025-S-175-N | B20: R025 | C20: S-175-N | D20: Laboratory specimen | E20: BOU2011 | F20: Steel | H20: 3000 | I20: 2500 | J20: 175 | L20: 2000 | O20: 42.3 | P20: Compression-test basis not extracted; no cube-cylinder conversion | Q20: 11.3 | S20: 230 | T20: 0.3 | U20: 200 | V20: 453 | W20: As reported; FRP rupture versus steel yield must be retained | X20: 25 | Y20: 25 | Z20: 600 | AA20: 250 | AC20: Edge restrained | AD20: Single central patch; monotonic | AE20: Punching shear | AG20: Author-deposited primary full text, table transcription | AH20: Tables 1–3; journal pp. 3957–3959 | AI20: https://doi.org/10.1016/j.conbuildmat.2011.04.028
A21: R025-C-175-N | B21: R025 | C21: C-175-N | D21: Laboratory specimen | E21: BOU2011 | F21: CFRP | H21: 3000 | I21: 2500 | J21: 175 | L21: 2000 | O21: 40.3 | P21: Compression-test basis not extracted; no cube-cylinder conversion | Q21: 9.5 | S21: 125 | T21: 0.4 | U21: 122 | V21: 1444 | W21: As reported; FRP rupture versus steel yield must be retained | X21: 25 | Y21: 25 | Z21: 600 | AA21: 250 | AC21: Edge restrained | AD21: Single central patch; monotonic | AE21: Punching shear | AG21: Author-deposited primary full text, table transcription | AH21: Tables 1–3; journal pp. 3957–3959 | AI21: https://doi.org/10.1016/j.conbuildmat.2011.04.028
A22: R012-SG1a | B22: R012 | C22: SG1a | D22: Laboratory specimen | E22: ALS2012 | F22: GFRP | H22: 2350 | I22: 500 | J22: 120 | L22: 2100 | M22: 750 | O22: 51 | P22: Cube strength; no conversion | Q22: 6.35 | T22: 0.35 | U22: 38.9 | V22: 600 | W22: As reported; FRP rupture versus steel yield must be retained | X22: 27.5 | AC22: Simply supported | AD22: Four-point; one service-load cycle then loading to failure | AE22: Rebar rupture | AF22: Concrete strength is CUBE strength; do not treat as cylinder fc. Nominal reinforcement ratio reported per series; actual cover differs. No numerical raw ultimate load or deflection extracted from curves. | AG22: Primary table transcription | AH22: Tables1,3,4; manuscript pp.14–15; Fig2 p.17 | AI22: https://eprints.whiterose.ac.uk/id/eprint/85515/1/Deflection%20behaviour%20of%20FRP%20reinforced%20concrete%20beams%20and%20slabs-%20An%20experimental%20investigation.pdf
A23: R012-SG1b | B23: R012 | C23: SG1b | D23: Laboratory specimen | E23: ALS2012 | F23: GFRP | H23: 2350 | I23: 500 | J23: 120 | L23: 2100 | M23: 750 | O23: 51 | P23: Cube strength; no conversion | Q23: 6.35 | T23: 0.35 | U23: 38.9 | V23: 600 | W23: As reported; FRP rupture versus steel yield must be retained | X23: 27.5 | AC23: Simply supported | AD23: Four-point; one service-load cycle then loading to failure | AE23: Rebar rupture | AF23: Concrete strength is CUBE strength; do not treat as cylinder fc. Nominal reinforcement ratio reported per series; actual cover differs. No numerical raw ultimate load or deflection extracted from curves. | AG23: Primary table transcription | AH23: Tables1,3,4; manuscript pp.14–15; Fig2 p.17 | AI23: https://eprints.whiterose.ac.uk/id/eprint/85515/1/Deflection%20behaviour%20of%20FRP%20reinforced%20concrete%20beams%20and%20slabs-%20An%20experimental%20investigation.pdf
A24: R012-SG2a | B24: R012 | C24: SG2a | D24: Laboratory specimen | E24: ALS2012 | F24: GFRP | H24: 2350 | I24: 500 | J24: 120 | L24: 2100 | M24: 750 | O24: 46.2 | P24: Cube strength; no conversion | Q24: 9.53 | T24: 0.79 | U24: 42.8 | V24: 665 | W24: As reported; FRP rupture versus steel yield must be retained | X24: 31 | AC24: Simply supported | AD24: Four-point; one service-load cycle then loading to failure | AE24: Almost balanced | AF24: Concrete strength is CUBE strength; do not treat as cylinder fc. Nominal reinforcement ratio reported per series; actual cover differs. No numerical raw ultimate load or deflection extracted from curves. | AG24: Primary table transcription | AH24: Tables1,3,4; manuscript pp.14–15; Fig2 p.17 | AI24: https://eprints.whiterose.ac.uk/id/eprint/85515/1/Deflection%20behaviour%20of%20FRP%20reinforced%20concrete%20beams%20and%20slabs-%20An%20experimental%20investigation.pdf
A25: R012-SG2b | B25: R012 | C25: SG2b | D25: Laboratory specimen | E25: ALS2012 | F25: GFRP | H25: 2350 | I25: 500 | J25: 120 | L25: 2100 | M25: 750 | O25: 46.2 | P25: Cube strength; no conversion | Q25: 9.53 | T25: 0.79 | U25: 42.8 | V25: 665 | W25: As reported; FRP rupture versus steel yield must be retained | X25: 31 | AC25: Simply supported | AD25: Four-point; one service-load cycle then loading to failure | AE25: Almost balanced | AF25: Concrete strength is CUBE strength; do not treat as cylinder fc. Nominal reinforcement ratio reported per series; actual cover differs. No numerical raw ultimate load or deflection extracted from curves. | AG25: Primary table transcription | AH25: Tables1,3,4; manuscript pp.14–15; Fig2 p.17 | AI25: https://eprints.whiterose.ac.uk/id/eprint/85515/1/Deflection%20behaviour%20of%20FRP%20reinforced%20concrete%20beams%20and%20slabs-%20An%20experimental%20investigation.pdf
A26: R012-SG3a | B26: R012 | C26: SG3a | D26: Laboratory specimen | E26: ALS2012 | F26: GFRP | H26: 2350 | I26: 500 | J26: 120 | L26: 2100 | M26: 750 | O26: 45.9 | P26: Cube strength; no conversion | Q26: 19.05 | T26: 3.33 | U26: 42 | V26: 670 | W26: As reported; FRP rupture versus steel yield must be retained | X26: 40 | AC26: Simply supported | AD26: Four-point; one service-load cycle then loading to failure | AE26: Concrete crushing | AF26: Concrete strength is CUBE strength; do not treat as cylinder fc. Nominal reinforcement ratio reported per series; actual cover differs. No numerical raw ultimate load or deflection extracted from curves. | AG26: Primary table transcription | AH26: Tables1,3,4; manuscript pp.14–15; Fig2 p.17 | AI26: https://eprints.whiterose.ac.uk/id/eprint/85515/1/Deflection%20behaviour%20of%20FRP%20reinforced%20concrete%20beams%20and%20slabs-%20An%20experimental%20investigation.pdf
A27: R012-SG3b | B27: R012 | C27: SG3b | D27: Laboratory specimen | E27: ALS2012 | F27: GFRP | H27: 2350 | I27: 500 | J27: 120 | L27: 2100 | M27: 750 | O27: 45.9 | P27: Cube strength; no conversion | Q27: 19.05 | T27: 3.33 | U27: 42 | V27: 670 | W27: As reported; FRP rupture versus steel yield must be retained | X27: 40 | AC27: Simply supported | AD27: Four-point; one service-load cycle then loading to failure | AE27: Concrete crushing | AF27: Concrete strength is CUBE strength; do not treat as cylinder fc. Nominal reinforcement ratio reported per series; actual cover differs. No numerical raw ultimate load or deflection extracted from curves. | AG27: Primary table transcription | AH27: Tables1,3,4; manuscript pp.14–15; Fig2 p.17 | AI27: https://eprints.whiterose.ac.uk/id/eprint/85515/1/Deflection%20behaviour%20of%20FRP%20reinforced%20concrete%20beams%20and%20slabs-%20An%20experimental%20investigation.pdf
